(dp1
S'output'
p2
S'<type \'exceptions.RuntimeError\'> Failure to connect, tried 5 times:\nTraceback (most recent call last):\n  File "/home/nairelys/Descargas/Sigulab/web2py/gluon/packages/dal/pydal/base.py", line 455, in __init__\n    self._adapter = adapter(**kwargs)\n  File "/home/nairelys/Descargas/Sigulab/web2py/gluon/packages/dal/pydal/adapters/postgres.py", line 25, in __call__\n    return AdapterMeta.__call__(cls, *args, **kwargs)\n  File "/home/nairelys/Descargas/Sigulab/web2py/gluon/packages/dal/pydal/adapters/__init__.py", line 40, in __call__\n    obj = super(AdapterMeta, cls).__call__(*args, **kwargs)\n  File "/home/nairelys/Descargas/Sigulab/web2py/gluon/packages/dal/pydal/adapters/postgres.py", line 48, in __init__\n    driver_args, adapter_args, do_connect, after_connection)\n  File "/home/nairelys/Descargas/Sigulab/web2py/gluon/packages/dal/pydal/adapters/base.py", line 368, in __init__\n    super(SQLAdapter, self).__init__(*args, **kwargs)\n  File "/home/nairelys/Descargas/Sigulab/web2py/gluon/packages/dal/pydal/adapters/base.py", line 52, in __init__\n    self.reconnect()\n  File "/home/nairelys/Descargas/Sigulab/web2py/gluon/packages/dal/pydal/helpers/classes.py", line 181, in _reconnect_and_configure\n    self._connection_reconnect()\n  File "/home/nairelys/Descargas/Sigulab/web2py/gluon/packages/dal/pydal/connection.py", line 172, in reconnect\n    self.connection = self.connector()\n  File "/home/nairelys/Descargas/Sigulab/web2py/gluon/packages/dal/pydal/adapters/postgres.py", line 105, in connector\n    return self.driver.connect(**self.driver_args)\n  File "/usr/lib/python2.7/dist-packages/psycopg2/__init__.py", line 179, in connect\n    connection_factory=connection_factory, async=async)\nOperationalError: FATAL:  database "sigulab2" does not exist\n\n'
p3
sS'layer'
p4
S'/home/nairelys/Descargas/Sigulab/web2py/applications/sigulab2/models/db.py'
p5
sS'code'
p6
S'<code object <module> at 0xac7bead0, file "/home/nairelys/Descargas/Sigulab/web2py/applications/sigulab2/models/db.py", line 4>'
p7
sS'snapshot'
p8
(dp9
sS'traceback'
p10
S'Traceback (most recent call last):\n  File "/home/nairelys/Descargas/Sigulab/web2py/gluon/restricted.py", line 219, in restricted\n    exec(ccode, environment)\n  File "/home/nairelys/Descargas/Sigulab/web2py/applications/sigulab2/models/db.py", line 38, in <module>\n    check_reserved=[\'all\'])\n  File "/home/nairelys/Descargas/Sigulab/web2py/gluon/packages/dal/pydal/base.py", line 170, in __call__\n    obj = super(MetaDAL, cls).__call__(*args, **kwargs)\n  File "/home/nairelys/Descargas/Sigulab/web2py/gluon/packages/dal/pydal/base.py", line 475, in __init__\n    "Failure to connect, tried %d times:\\n%s" % (attempts, tb)\nRuntimeError: Failure to connect, tried 5 times:\nTraceback (most recent call last):\n  File "/home/nairelys/Descargas/Sigulab/web2py/gluon/packages/dal/pydal/base.py", line 455, in __init__\n    self._adapter = adapter(**kwargs)\n  File "/home/nairelys/Descargas/Sigulab/web2py/gluon/packages/dal/pydal/adapters/postgres.py", line 25, in __call__\n    return AdapterMeta.__call__(cls, *args, **kwargs)\n  File "/home/nairelys/Descargas/Sigulab/web2py/gluon/packages/dal/pydal/adapters/__init__.py", line 40, in __call__\n    obj = super(AdapterMeta, cls).__call__(*args, **kwargs)\n  File "/home/nairelys/Descargas/Sigulab/web2py/gluon/packages/dal/pydal/adapters/postgres.py", line 48, in __init__\n    driver_args, adapter_args, do_connect, after_connection)\n  File "/home/nairelys/Descargas/Sigulab/web2py/gluon/packages/dal/pydal/adapters/base.py", line 368, in __init__\n    super(SQLAdapter, self).__init__(*args, **kwargs)\n  File "/home/nairelys/Descargas/Sigulab/web2py/gluon/packages/dal/pydal/adapters/base.py", line 52, in __init__\n    self.reconnect()\n  File "/home/nairelys/Descargas/Sigulab/web2py/gluon/packages/dal/pydal/helpers/classes.py", line 181, in _reconnect_and_configure\n    self._connection_reconnect()\n  File "/home/nairelys/Descargas/Sigulab/web2py/gluon/packages/dal/pydal/connection.py", line 172, in reconnect\n    self.connection = self.connector()\n  File "/home/nairelys/Descargas/Sigulab/web2py/gluon/packages/dal/pydal/adapters/postgres.py", line 105, in connector\n    return self.driver.connect(**self.driver_args)\n  File "/usr/lib/python2.7/dist-packages/psycopg2/__init__.py", line 179, in connect\n    connection_factory=connection_factory, async=async)\nOperationalError: FATAL:  database "sigulab2" does not exist\n\n\n'
p11
s.